"LogFile","LineNumber","Keyword","LineText"
"D:\MAGIC\outputs\logs\11A_error_log_monitor_READY.log","1","error","Running 11A_error_log_monitor_READY.py placeholder."
"D:\MAGIC\outputs\logs\11A_error_log_monitor_READY.py.log","1","error","Running 11A_error_log_monitor_READY.py placeholder."
"D:\MAGIC\outputs\logs\11F_error_pattern_analyzer_READY.log","1","error","âœ… [11F_error_pattern_analyzer_READY.py] executed successfully (stub mode)."
"D:\MAGIC\outputs\logs\11F_error_pattern_analyzer_READY.py.log","1","error","âœ… [11F_error_pattern_analyzer_READY.py] executed successfully (stub mode)."
"D:\MAGIC\outputs\logs\11R_silent_error_logger_READY.log","1","error","âœ… [11R_silent_error_logger_READY.py] executed successfully (stub mode)."
"D:\MAGIC\outputs\logs\11R_silent_error_logger_READY.py.log","1","error","âœ… [11R_silent_error_logger_READY.py] executed successfully (stub mode)."
"D:\MAGIC\outputs\logs\99Z_file_not_found_test_READY.log","1","traceback","Traceback (most recent call last):"
"D:\MAGIC\outputs\logs\99Z_file_not_found_test_READY.log","5","error","FileNotFoundError: [Errno 2] No such file or directory: 'non_existent_input.txt'"
"D:\MAGIC\outputs\logs\99Z_file_not_found_test_READY.py.log","1","traceback","Traceback (most recent call last):"
"D:\MAGIC\outputs\logs\99Z_file_not_found_test_READY.py.log","5","error","FileNotFoundError: [Errno 2] No such file or directory: 'non_existent_input.txt'"
"D:\MAGIC\outputs\logs\99Z_import_error_test_READY.log","1","traceback","Traceback (most recent call last):"
"D:\MAGIC\outputs\logs\99Z_import_error_test_READY.log","2","error","File ""D:\MAGIC\scripts\phase99\module_ZZ\99Z_import_error_test_READY.py"", line 1, in <module>"
"D:\MAGIC\outputs\logs\99Z_import_error_test_READY.log","4","error","ModuleNotFoundError: No module named 'non_existent_module'"
"D:\MAGIC\outputs\logs\99Z_import_error_test_READY.py.log","1","traceback","Traceback (most recent call last):"
"D:\MAGIC\outputs\logs\99Z_import_error_test_READY.py.log","2","error","File ""D:\MAGIC\scripts\phase99\module_ZZ\99Z_import_error_test_READY.py"", line 1, in <module>"
"D:\MAGIC\outputs\logs\99Z_import_error_test_READY.py.log","4","error","ModuleNotFoundError: No module named 'non_existent_module'"
"D:\MAGIC\outputs\logs\99Z_unicode_error_test_READY.log","1","traceback","Traceback (most recent call last):"
"D:\MAGIC\outputs\logs\99Z_unicode_error_test_READY.log","2","error","File ""D:\MAGIC\scripts\phase99\module_ZZ\99Z_unicode_error_test_READY.py"", line 3, in <module>"
"D:\MAGIC\outputs\logs\99Z_unicode_error_test_READY.log","5","error","UnicodeEncodeError: 'ascii' codec can't encode characters in position 12-14: ordinal not in range(128)"
"D:\MAGIC\outputs\logs\99Z_unicode_error_test_READY.py.log","1","traceback","Traceback (most recent call last):"
"D:\MAGIC\outputs\logs\99Z_unicode_error_test_READY.py.log","2","error","File ""D:\MAGIC\scripts\phase99\module_ZZ\99Z_unicode_error_test_READY.py"", line 3, in <module>"
"D:\MAGIC\outputs\logs\99Z_unicode_error_test_READY.py.log","5","error","UnicodeEncodeError: 'ascii' codec can't encode characters in position 12-14: ordinal not in range(128)"
"D:\MAGIC\outputs\logs\module_A\11A_error_log_monitor_READY.py\11A_error_log_monitor_READY.py_2025-08-05_11-24-17.log","1","error","Running 11A_error_log_monitor_READY.py placeholder."
"D:\MAGIC\outputs\logs\module_F\11F_error_pattern_analyzer_READY.py\11F_error_pattern_analyzer_READY.py_2025-08-05_11-24-17.log","1","error","✅ [11F_error_pattern_analyzer_READY.py] executed successfully (stub mode)."
"D:\MAGIC\outputs\logs\module_R\11R_silent_error_logger_READY.py\11R_silent_error_logger_READY.py_2025-08-05_11-24-17.log","1","error","✅ [11R_silent_error_logger_READY.py] executed successfully (stub mode)."
"D:\MAGIC\outputs\logs\module_ZZ\99Z_file_not_found_test_READY.py\99Z_file_not_found_test_READY.py_2025-08-04_17-45-37.log","1","traceback","Traceback (most recent call last):"
"D:\MAGIC\outputs\logs\module_ZZ\99Z_file_not_found_test_READY.py\99Z_file_not_found_test_READY.py_2025-08-04_17-45-37.log","5","error","FileNotFoundError: [Errno 2] No such file or directory: 'non_existent_input.txt'"
"D:\MAGIC\outputs\logs\module_ZZ\99Z_import_error_test_READY.py\99Z_import_error_test_READY.py_2025-08-04_17-45-37.log","1","traceback","Traceback (most recent call last):"
"D:\MAGIC\outputs\logs\module_ZZ\99Z_import_error_test_READY.py\99Z_import_error_test_READY.py_2025-08-04_17-45-37.log","2","error","File ""D:\MAGIC\scripts\phase99\module_ZZ\99Z_import_error_test_READY.py"", line 1, in <module>"
"D:\MAGIC\outputs\logs\module_ZZ\99Z_import_error_test_READY.py\99Z_import_error_test_READY.py_2025-08-04_17-45-37.log","4","error","ModuleNotFoundError: No module named 'non_existent_module'"
"D:\MAGIC\outputs\logs\module_ZZ\99Z_import_error_test_READY.py\99Z_import_error_test_READY.py_2025-08-05_11-24-17.log","1","traceback","Traceback (most recent call last):"
"D:\MAGIC\outputs\logs\module_ZZ\99Z_import_error_test_READY.py\99Z_import_error_test_READY.py_2025-08-05_11-24-17.log","2","error","File ""D:\MAGIC\scripts\phase99\module_ZZ\99Z_import_error_test_READY.py"", line 1, in <module>"
"D:\MAGIC\outputs\logs\module_ZZ\99Z_import_error_test_READY.py\99Z_import_error_test_READY.py_2025-08-05_11-24-17.log","4","error","ModuleNotFoundError: No module named 'non_existent_module'"
"D:\MAGIC\outputs\logs\module_ZZ\99Z_unicode_error_test_READY.py\99Z_unicode_error_test_READY.py_2025-08-04_17-45-37.log","1","traceback","Traceback (most recent call last):"
"D:\MAGIC\outputs\logs\module_ZZ\99Z_unicode_error_test_READY.py\99Z_unicode_error_test_READY.py_2025-08-04_17-45-37.log","2","error","File ""D:\MAGIC\scripts\phase99\module_ZZ\99Z_unicode_error_test_READY.py"", line 3, in <module>"
"D:\MAGIC\outputs\logs\module_ZZ\99Z_unicode_error_test_READY.py\99Z_unicode_error_test_READY.py_2025-08-04_17-45-37.log","5","error","UnicodeEncodeError: 'ascii' codec can't encode characters in position 12-14: ordinal not in range(128)"
"D:\MAGIC\outputs\logs\module_ZZ\99Z_unicode_error_test_READY.py\99Z_unicode_error_test_READY.py_2025-08-05_11-24-17.log","1","traceback","Traceback (most recent call last):"
"D:\MAGIC\outputs\logs\module_ZZ\99Z_unicode_error_test_READY.py\99Z_unicode_error_test_READY.py_2025-08-05_11-24-17.log","2","error","File ""D:\MAGIC\scripts\phase99\module_ZZ\99Z_unicode_error_test_READY.py"", line 3, in <module>"
"D:\MAGIC\outputs\logs\module_ZZ\99Z_unicode_error_test_READY.py\99Z_unicode_error_test_READY.py_2025-08-05_11-24-17.log","5","error","UnicodeEncodeError: 'ascii' codec can't encode characters in position 12-14: ordinal not in range(128)"
"D:\MAGIC\outputs\logs\phase01_module_D\01D_error_logging_sink_READY.log","2","error","Running script: D:/MAGIC/scripts/phase01/module_D/01D_error_logging_sink_READY.py"
"D:\MAGIC\outputs\logs\phase01_module_D\01D_error_logging_sink_READY.log","11","error","Running script: D:/MAGIC/scripts/phase01/module_D/01D_error_logging_sink_READY.py"
"D:\MAGIC\outputs\logs\phase01_module_D\01D_error_logging_sink_READY.log","21","error","Running script: D:/MAGIC/scripts/phase01/module_D/01D_error_logging_sink_READY.py"
"D:\MAGIC\outputs\logs\phase01_module_D\01D_error_logging_sink_READY.log","31","error","Running script: D:/MAGIC/scripts/phase01/module_D/01D_error_logging_sink_READY.py"
"D:\MAGIC\outputs\logs\phase04_module_D\04D_error_category_breakdown_READY.log","2","error","Running script: D:/MAGIC/scripts/phase04/module_D/04D_error_category_breakdown_READY.py"
"D:\MAGIC\outputs\logs\phase04_module_D\04D_error_category_breakdown_READY.log","11","error","Running script: D:/MAGIC/scripts/phase04/module_D/04D_error_category_breakdown_READY.py"
"D:\MAGIC\outputs\logs\phase04_module_D\04D_error_category_breakdown_READY.log","21","error","Running script: D:/MAGIC/scripts/phase04/module_D/04D_error_category_breakdown_READY.py"
"D:\MAGIC\outputs\logs\phase04_module_D\04D_error_category_breakdown_READY.log","31","error","Running script: D:/MAGIC/scripts/phase04/module_D/04D_error_category_breakdown_READY.py"
"D:\MAGIC\outputs\logs\phase04_module_D\04D_error_log_viewer_READY.log","2","error","Running script: D:/MAGIC/scripts/phase04/module_D/04D_error_log_viewer_READY.py"
"D:\MAGIC\outputs\logs\phase04_module_D\04D_error_log_viewer_READY.log","11","error","Running script: D:/MAGIC/scripts/phase04/module_D/04D_error_log_viewer_READY.py"
"D:\MAGIC\outputs\logs\phase04_module_D\04D_error_log_viewer_READY.log","21","error","Running script: D:/MAGIC/scripts/phase04/module_D/04D_error_log_viewer_READY.py"
"D:\MAGIC\outputs\logs\phase04_module_D\04D_error_log_viewer_READY.log","31","error","Running script: D:/MAGIC/scripts/phase04/module_D/04D_error_log_viewer_READY.py"
"D:\MAGIC\outputs\logs\phase06_module_H\06H_error_recovery_republishing_READY.log","2","error","Running script: D:/MAGIC/scripts/phase06/module_H/06H_error_recovery_republishing_READY.py"
"D:\MAGIC\outputs\logs\phase06_module_H\06H_error_recovery_republishing_READY.log","11","error","Running script: D:/MAGIC/scripts/phase06/module_H/06H_error_recovery_republishing_READY.py"
"D:\MAGIC\outputs\logs\phase06_module_H\06H_error_recovery_republishing_READY.log","21","error","Running script: D:/MAGIC/scripts/phase06/module_H/06H_error_recovery_republishing_READY.py"
"D:\MAGIC\outputs\logs\phase06_module_H\06H_error_recovery_republishing_READY.log","31","error","Running script: D:/MAGIC/scripts/phase06/module_H/06H_error_recovery_republishing_READY.py"
"D:\MAGIC\outputs\logs\phase08_module_O\08O_funnel_roi_traceback_engine_READY.log","2","traceback","Running script: D:/MAGIC/scripts/phase08/module_O/08O_funnel_roi_traceback_engine_READY.py"
"D:\MAGIC\outputs\logs\phase08_module_O\08O_funnel_roi_traceback_engine_READY.log","11","traceback","Running script: D:/MAGIC/scripts/phase08/module_O/08O_funnel_roi_traceback_engine_READY.py"
"D:\MAGIC\outputs\logs\phase08_module_O\08O_funnel_roi_traceback_engine_READY.log","21","traceback","Running script: D:/MAGIC/scripts/phase08/module_O/08O_funnel_roi_traceback_engine_READY.py"
"D:\MAGIC\outputs\logs\phase08_module_O\08O_funnel_roi_traceback_engine_READY.log","31","traceback","Running script: D:/MAGIC/scripts/phase08/module_O/08O_funnel_roi_traceback_engine_READY.py"
"D:\MAGIC\outputs\logs\phase11_module_A\11A_error_log_monitor_READY.log","2","error","Running script: D:/MAGIC/scripts/phase11/module_A/11A_error_log_monitor_READY.py"
"D:\MAGIC\outputs\logs\phase11_module_A\11A_error_log_monitor_READY.log","5","error","Running 11A_error_log_monitor_READY.py placeholder."
"D:\MAGIC\outputs\logs\phase11_module_A\11A_error_log_monitor_READY.log","12","error","Running script: D:/MAGIC/scripts/phase11/module_A/11A_error_log_monitor_READY.py"
"D:\MAGIC\outputs\logs\phase11_module_A\11A_error_log_monitor_READY.log","15","error","Running 11A_error_log_monitor_READY.py placeholder."
"D:\MAGIC\outputs\logs\phase11_module_A\11A_error_log_monitor_READY.log","23","error","Running script: D:/MAGIC/scripts/phase11/module_A/11A_error_log_monitor_READY.py"
"D:\MAGIC\outputs\logs\phase11_module_A\11A_error_log_monitor_READY.log","26","error","Running 11A_error_log_monitor_READY.py placeholder."
"D:\MAGIC\outputs\logs\phase11_module_A\11A_error_log_monitor_READY.log","34","error","Running script: D:/MAGIC/scripts/phase11/module_A/11A_error_log_monitor_READY.py"
"D:\MAGIC\outputs\logs\phase11_module_A\11A_error_log_monitor_READY.log","37","error","Running 11A_error_log_monitor_READY.py placeholder."
"D:\MAGIC\outputs\logs\phase11_module_A\11A_error_log_monitor_READY.log","47","error","Running 11A_error_log_monitor_READY.py placeholder."
"D:\MAGIC\outputs\logs\phase11_module_F\11F_error_pattern_analyzer_READY.log","2","error","Running script: D:/MAGIC/scripts/phase11/module_F/11F_error_pattern_analyzer_READY.py"
"D:\MAGIC\outputs\logs\phase11_module_F\11F_error_pattern_analyzer_READY.log","5","error","âœ… [11F_error_pattern_analyzer_READY.py] executed successfully (stub mode)."
"D:\MAGIC\outputs\logs\phase11_module_F\11F_error_pattern_analyzer_READY.log","12","error","Running script: D:/MAGIC/scripts/phase11/module_F/11F_error_pattern_analyzer_READY.py"
"D:\MAGIC\outputs\logs\phase11_module_F\11F_error_pattern_analyzer_READY.log","15","error","âœ… [11F_error_pattern_analyzer_READY.py] executed successfully (stub mode)."
"D:\MAGIC\outputs\logs\phase11_module_F\11F_error_pattern_analyzer_READY.log","23","error","Running script: D:/MAGIC/scripts/phase11/module_F/11F_error_pattern_analyzer_READY.py"
"D:\MAGIC\outputs\logs\phase11_module_F\11F_error_pattern_analyzer_READY.log","26","error","âœ… [11F_error_pattern_analyzer_READY.py] executed successfully (stub mode)."
"D:\MAGIC\outputs\logs\phase11_module_F\11F_error_pattern_analyzer_READY.log","34","error","Running script: D:/MAGIC/scripts/phase11/module_F/11F_error_pattern_analyzer_READY.py"
"D:\MAGIC\outputs\logs\phase11_module_F\11F_error_pattern_analyzer_READY.log","37","error","âœ… [11F_error_pattern_analyzer_READY.py] executed successfully (stub mode)."
"D:\MAGIC\outputs\logs\phase11_module_F\11F_error_pattern_analyzer_READY.log","47","error","âœ… [11F_error_pattern_analyzer_READY.py] executed successfully (stub mode)."
"D:\MAGIC\outputs\logs\phase11_module_R\11R_silent_error_logger_READY.log","2","error","Running script: D:/MAGIC/scripts/phase11/module_R/11R_silent_error_logger_READY.py"
"D:\MAGIC\outputs\logs\phase11_module_R\11R_silent_error_logger_READY.log","5","error","âœ… [11R_silent_error_logger_READY.py] executed successfully (stub mode)."
"D:\MAGIC\outputs\logs\phase11_module_R\11R_silent_error_logger_READY.log","12","error","Running script: D:/MAGIC/scripts/phase11/module_R/11R_silent_error_logger_READY.py"
"D:\MAGIC\outputs\logs\phase11_module_R\11R_silent_error_logger_READY.log","15","error","âœ… [11R_silent_error_logger_READY.py] executed successfully (stub mode)."
"D:\MAGIC\outputs\logs\phase11_module_R\11R_silent_error_logger_READY.log","23","error","Running script: D:/MAGIC/scripts/phase11/module_R/11R_silent_error_logger_READY.py"
"D:\MAGIC\outputs\logs\phase11_module_R\11R_silent_error_logger_READY.log","26","error","âœ… [11R_silent_error_logger_READY.py] executed successfully (stub mode)."
"D:\MAGIC\outputs\logs\phase11_module_R\11R_silent_error_logger_READY.log","34","error","Running script: D:/MAGIC/scripts/phase11/module_R/11R_silent_error_logger_READY.py"
"D:\MAGIC\outputs\logs\phase11_module_R\11R_silent_error_logger_READY.log","37","error","âœ… [11R_silent_error_logger_READY.py] executed successfully (stub mode)."
"D:\MAGIC\outputs\logs\phase11_module_R\11R_silent_error_logger_READY.log","47","error","âœ… [11R_silent_error_logger_READY.py] executed successfully (stub mode)."
"D:\MAGIC\outputs\logs\phase99\module_ZZ\99Z_file_not_found_test_READY.py_17-39-08.log","9","traceback","Traceback (most recent call last):"
"D:\MAGIC\outputs\logs\phase99\module_ZZ\99Z_file_not_found_test_READY.py_17-39-08.log","13","error","FileNotFoundError: [Errno 2] No such file or directory: 'non_existent_input.txt'"
"D:\MAGIC\outputs\logs\phase99\module_ZZ\99Z_file_not_found_test_READY.py_17-42-52.log","9","traceback","Traceback (most recent call last):"
"D:\MAGIC\outputs\logs\phase99\module_ZZ\99Z_file_not_found_test_READY.py_17-42-52.log","13","error","FileNotFoundError: [Errno 2] No such file or directory: 'non_existent_input.txt'"
"D:\MAGIC\outputs\logs\phase99\module_ZZ\99Z_file_not_found_test_READY.py_2025-08-04_17-44-22.log","6","traceback","Traceback (most recent call last):"
"D:\MAGIC\outputs\logs\phase99\module_ZZ\99Z_file_not_found_test_READY.py_2025-08-04_17-44-22.log","10","error","FileNotFoundError: [Errno 2] No such file or directory: 'non_existent_input.txt'"
"D:\MAGIC\outputs\logs\phase99\module_ZZ\99Z_file_not_found_test_READY.py_2025-08-04_17-44-22.log","16","traceback","Traceback (most recent call last):"
"D:\MAGIC\outputs\logs\phase99\module_ZZ\99Z_file_not_found_test_READY.py_2025-08-04_17-44-22.log","20","error","FileNotFoundError: [Errno 2] No such file or directory: 'non_existent_input.txt'"
"D:\MAGIC\outputs\logs\phase99\module_ZZ\99Z_file_not_found_test_READY.py_2025-08-04_17-44-22.log","26","traceback","Traceback (most recent call last):"
"D:\MAGIC\outputs\logs\phase99\module_ZZ\99Z_file_not_found_test_READY.py_2025-08-04_17-44-22.log","30","error","FileNotFoundError: [Errno 2] No such file or directory: 'non_existent_input.txt'"
"D:\MAGIC\outputs\logs\phase99\module_ZZ\99Z_import_error_test_READY.py_17-39-08.log","1","error","=== Script: 99Z_import_error_test_READY.py ==="
"D:\MAGIC\outputs\logs\phase99\module_ZZ\99Z_import_error_test_READY.py_17-39-08.log","9","traceback","Traceback (most recent call last):"
"D:\MAGIC\outputs\logs\phase99\module_ZZ\99Z_import_error_test_READY.py_17-39-08.log","10","error","File ""D:\MAGIC\scripts\phase99\module_ZZ\99Z_import_error_test_READY.py"", line 1, in <module>"
"D:\MAGIC\outputs\logs\phase99\module_ZZ\99Z_import_error_test_READY.py_17-39-08.log","12","error","ModuleNotFoundError: No module named 'non_existent_module'"
"D:\MAGIC\outputs\logs\phase99\module_ZZ\99Z_import_error_test_READY.py_17-42-52.log","1","error","=== Script: 99Z_import_error_test_READY.py ==="
"D:\MAGIC\outputs\logs\phase99\module_ZZ\99Z_import_error_test_READY.py_17-42-52.log","9","traceback","Traceback (most recent call last):"
"D:\MAGIC\outputs\logs\phase99\module_ZZ\99Z_import_error_test_READY.py_17-42-52.log","10","error","File ""D:\MAGIC\scripts\phase99\module_ZZ\99Z_import_error_test_READY.py"", line 1, in <module>"
"D:\MAGIC\outputs\logs\phase99\module_ZZ\99Z_import_error_test_READY.py_17-42-52.log","12","error","ModuleNotFoundError: No module named 'non_existent_module'"
"D:\MAGIC\outputs\logs\phase99\module_ZZ\99Z_import_error_test_READY.py_2025-08-04_17-44-22.log","6","traceback","Traceback (most recent call last):"
"D:\MAGIC\outputs\logs\phase99\module_ZZ\99Z_import_error_test_READY.py_2025-08-04_17-44-22.log","7","error","File ""D:\MAGIC\scripts\phase99\module_ZZ\99Z_import_error_test_READY.py"", line 1, in <module>"
"D:\MAGIC\outputs\logs\phase99\module_ZZ\99Z_import_error_test_READY.py_2025-08-04_17-44-22.log","9","error","ModuleNotFoundError: No module named 'non_existent_module'"
"D:\MAGIC\outputs\logs\phase99\module_ZZ\99Z_import_error_test_READY.py_2025-08-04_17-44-22.log","15","traceback","Traceback (most recent call last):"
"D:\MAGIC\outputs\logs\phase99\module_ZZ\99Z_import_error_test_READY.py_2025-08-04_17-44-22.log","16","error","File ""D:\MAGIC\scripts\phase99\module_ZZ\99Z_import_error_test_READY.py"", line 1, in <module>"
"D:\MAGIC\outputs\logs\phase99\module_ZZ\99Z_import_error_test_READY.py_2025-08-04_17-44-22.log","18","error","ModuleNotFoundError: No module named 'non_existent_module'"
"D:\MAGIC\outputs\logs\phase99\module_ZZ\99Z_import_error_test_READY.py_2025-08-04_17-44-22.log","24","traceback","Traceback (most recent call last):"
"D:\MAGIC\outputs\logs\phase99\module_ZZ\99Z_import_error_test_READY.py_2025-08-04_17-44-22.log","25","error","File ""D:\MAGIC\scripts\phase99\module_ZZ\99Z_import_error_test_READY.py"", line 1, in <module>"
"D:\MAGIC\outputs\logs\phase99\module_ZZ\99Z_import_error_test_READY.py_2025-08-04_17-44-22.log","27","error","ModuleNotFoundError: No module named 'non_existent_module'"
"D:\MAGIC\outputs\logs\phase99\module_ZZ\99Z_unicode_error_test_READY.py_17-39-08.log","1","error","=== Script: 99Z_unicode_error_test_READY.py ==="
"D:\MAGIC\outputs\logs\phase99\module_ZZ\99Z_unicode_error_test_READY.py_17-39-08.log","9","traceback","Traceback (most recent call last):"
"D:\MAGIC\outputs\logs\phase99\module_ZZ\99Z_unicode_error_test_READY.py_17-39-08.log","10","error","File ""D:\MAGIC\scripts\phase99\module_ZZ\99Z_unicode_error_test_READY.py"", line 3, in <module>"
"D:\MAGIC\outputs\logs\phase99\module_ZZ\99Z_unicode_error_test_READY.py_17-39-08.log","13","error","UnicodeEncodeError: 'ascii' codec can't encode characters in position 12-14: ordinal not in range(128)"
"D:\MAGIC\outputs\logs\phase99\module_ZZ\99Z_unicode_error_test_READY.py_17-42-52.log","1","error","=== Script: 99Z_unicode_error_test_READY.py ==="
"D:\MAGIC\outputs\logs\phase99\module_ZZ\99Z_unicode_error_test_READY.py_17-42-52.log","9","traceback","Traceback (most recent call last):"
"D:\MAGIC\outputs\logs\phase99\module_ZZ\99Z_unicode_error_test_READY.py_17-42-52.log","10","error","File ""D:\MAGIC\scripts\phase99\module_ZZ\99Z_unicode_error_test_READY.py"", line 3, in <module>"
"D:\MAGIC\outputs\logs\phase99\module_ZZ\99Z_unicode_error_test_READY.py_17-42-52.log","13","error","UnicodeEncodeError: 'ascii' codec can't encode characters in position 12-14: ordinal not in range(128)"
"D:\MAGIC\outputs\logs\phase99\module_ZZ\99Z_unicode_error_test_READY.py_2025-08-04_17-44-22.log","6","traceback","Traceback (most recent call last):"
"D:\MAGIC\outputs\logs\phase99\module_ZZ\99Z_unicode_error_test_READY.py_2025-08-04_17-44-22.log","7","error","File ""D:\MAGIC\scripts\phase99\module_ZZ\99Z_unicode_error_test_READY.py"", line 3, in <module>"
"D:\MAGIC\outputs\logs\phase99\module_ZZ\99Z_unicode_error_test_READY.py_2025-08-04_17-44-22.log","10","error","UnicodeEncodeError: 'ascii' codec can't encode characters in position 12-14: ordinal not in range(128)"
"D:\MAGIC\outputs\logs\phase99\module_ZZ\99Z_unicode_error_test_READY.py_2025-08-04_17-44-22.log","16","traceback","Traceback (most recent call last):"
"D:\MAGIC\outputs\logs\phase99\module_ZZ\99Z_unicode_error_test_READY.py_2025-08-04_17-44-22.log","17","error","File ""D:\MAGIC\scripts\phase99\module_ZZ\99Z_unicode_error_test_READY.py"", line 3, in <module>"
"D:\MAGIC\outputs\logs\phase99\module_ZZ\99Z_unicode_error_test_READY.py_2025-08-04_17-44-22.log","20","error","UnicodeEncodeError: 'ascii' codec can't encode characters in position 12-14: ordinal not in range(128)"
"D:\MAGIC\outputs\logs\phase99\module_ZZ\99Z_unicode_error_test_READY.py_2025-08-04_17-44-22.log","26","traceback","Traceback (most recent call last):"
"D:\MAGIC\outputs\logs\phase99\module_ZZ\99Z_unicode_error_test_READY.py_2025-08-04_17-44-22.log","27","error","File ""D:\MAGIC\scripts\phase99\module_ZZ\99Z_unicode_error_test_READY.py"", line 3, in <module>"
"D:\MAGIC\outputs\logs\phase99\module_ZZ\99Z_unicode_error_test_READY.py_2025-08-04_17-44-22.log","30","error","UnicodeEncodeError: 'ascii' codec can't encode characters in position 12-14: ordinal not in range(128)"
"D:\MAGIC\outputs\logs\phase99\module_ZZ\99ZZ_dummy_script_v2_READY.py_17-39-08.log","9","error","No errors."
"D:\MAGIC\outputs\logs\phase99\module_ZZ\99ZZ_dummy_script_v2_READY.py_17-42-52.log","9","error","No errors."
"D:\MAGIC\outputs\logs\phase99_module_ZZ\99Z_import_error_test_READY.log","2","error","Running script: D:/MAGIC/scripts/phase99/module_ZZ/99Z_import_error_test_READY.py"
"D:\MAGIC\outputs\logs\phase99_module_ZZ\99Z_import_error_test_READY.log","7","traceback","Traceback (most recent call last):"
"D:\MAGIC\outputs\logs\phase99_module_ZZ\99Z_import_error_test_READY.log","8","error","File ""D:\MAGIC\scripts\phase99\module_ZZ\99Z_import_error_test_READY.py"", line 1, in <module>"
"D:\MAGIC\outputs\logs\phase99_module_ZZ\99Z_import_error_test_READY.log","10","error","ModuleNotFoundError: No module named 'non_existent_module'"
"D:\MAGIC\outputs\logs\phase99_module_ZZ\99Z_import_error_test_READY.log","15","error","Running script: D:/MAGIC/scripts/phase99/module_ZZ/99Z_import_error_test_READY.py"
"D:\MAGIC\outputs\logs\phase99_module_ZZ\99Z_import_error_test_READY.log","20","traceback","Traceback (most recent call last):"
"D:\MAGIC\outputs\logs\phase99_module_ZZ\99Z_import_error_test_READY.log","21","error","File ""D:\MAGIC\scripts\phase99\module_ZZ\99Z_import_error_test_READY.py"", line 1, in <module>"
"D:\MAGIC\outputs\logs\phase99_module_ZZ\99Z_import_error_test_READY.log","23","error","ModuleNotFoundError: No module named 'non_existent_module'"
"D:\MAGIC\outputs\logs\phase99_module_ZZ\99Z_import_error_test_READY.log","31","error","Running script: D:/MAGIC/scripts/phase99/module_ZZ/99Z_import_error_test_READY.py"
"D:\MAGIC\outputs\logs\phase99_module_ZZ\99Z_import_error_test_READY.log","36","traceback","Traceback (most recent call last):"
"D:\MAGIC\outputs\logs\phase99_module_ZZ\99Z_import_error_test_READY.log","37","error","File ""D:\MAGIC\scripts\phase99\module_ZZ\99Z_import_error_test_READY.py"", line 1, in <module>"
"D:\MAGIC\outputs\logs\phase99_module_ZZ\99Z_import_error_test_READY.log","39","error","ModuleNotFoundError: No module named 'non_existent_module'"
"D:\MAGIC\outputs\logs\phase99_module_ZZ\99Z_import_error_test_READY.log","47","error","Running script: D:/MAGIC/scripts/phase99/module_ZZ/99Z_import_error_test_READY.py"
"D:\MAGIC\outputs\logs\phase99_module_ZZ\99Z_import_error_test_READY.log","52","traceback","Traceback (most recent call last):"
"D:\MAGIC\outputs\logs\phase99_module_ZZ\99Z_import_error_test_READY.log","53","error","File ""D:\MAGIC\scripts\phase99\module_ZZ\99Z_import_error_test_READY.py"", line 1, in <module>"
"D:\MAGIC\outputs\logs\phase99_module_ZZ\99Z_import_error_test_READY.log","55","error","ModuleNotFoundError: No module named 'non_existent_module'"
"D:\MAGIC\outputs\logs\phase99_module_ZZ\99Z_import_error_test_READY.log","63","error","Running script: D:/MAGIC/scripts/phase99/module_ZZ/99Z_import_error_test_READY.py"
"D:\MAGIC\outputs\logs\phase99_module_ZZ\99Z_import_error_test_READY.log","68","traceback","Traceback (most recent call last):"
"D:\MAGIC\outputs\logs\phase99_module_ZZ\99Z_import_error_test_READY.log","69","error","File ""D:\MAGIC\scripts\phase99\module_ZZ\99Z_import_error_test_READY.py"", line 1, in <module>"
"D:\MAGIC\outputs\logs\phase99_module_ZZ\99Z_import_error_test_READY.log","71","error","ModuleNotFoundError: No module named 'non_existent_module'"
"D:\MAGIC\outputs\logs\phase99_module_ZZ\99Z_import_error_test_READY.log","79","error","Running script: D:/MAGIC/scripts/phase99/module_ZZ/99Z_import_error_test_READY.py"
"D:\MAGIC\outputs\logs\phase99_module_ZZ\99Z_import_error_test_READY.log","84","traceback","Traceback (most recent call last):"
"D:\MAGIC\outputs\logs\phase99_module_ZZ\99Z_import_error_test_READY.log","85","error","File ""D:\MAGIC\scripts\phase99\module_ZZ\99Z_import_error_test_READY.py"", line 1, in <module>"
"D:\MAGIC\outputs\logs\phase99_module_ZZ\99Z_import_error_test_READY.log","87","error","ModuleNotFoundError: No module named 'non_existent_module'"
"D:\MAGIC\outputs\logs\phase99_module_ZZ\99Z_import_error_test_READY.log","95","error","Running script: D:/MAGIC/scripts/phase99/module_ZZ/99Z_import_error_test_READY.py"
"D:\MAGIC\outputs\logs\phase99_module_ZZ\99Z_import_error_test_READY.log","100","traceback","Traceback (most recent call last):"
"D:\MAGIC\outputs\logs\phase99_module_ZZ\99Z_import_error_test_READY.log","101","error","File ""D:\MAGIC\scripts\phase99\module_ZZ\99Z_import_error_test_READY.py"", line 1, in <module>"
"D:\MAGIC\outputs\logs\phase99_module_ZZ\99Z_import_error_test_READY.log","103","error","ModuleNotFoundError: No module named 'non_existent_module'"
"D:\MAGIC\outputs\logs\phase99_module_ZZ\99Z_import_error_test_READY.log","115","traceback","Traceback (most recent call last):"
"D:\MAGIC\outputs\logs\phase99_module_ZZ\99Z_import_error_test_READY.log","116","error","File ""D:\MAGIC\scripts\phase99\module_ZZ\99Z_import_error_test_READY.py"", line 1, in <module>"
"D:\MAGIC\outputs\logs\phase99_module_ZZ\99Z_import_error_test_READY.log","118","error","ModuleNotFoundError: No module named 'non_existent_module'"
"D:\MAGIC\outputs\logs\phase99_module_ZZ\99Z_import_error_test_READY.log","128","traceback","Traceback (most recent call last):"
"D:\MAGIC\outputs\logs\phase99_module_ZZ\99Z_import_error_test_READY.log","129","error","File ""D:\MAGIC\scripts\phase99\module_ZZ\99Z_import_error_test_READY.py"", line 1, in <module>"
"D:\MAGIC\outputs\logs\phase99_module_ZZ\99Z_import_error_test_READY.log","131","error","ModuleNotFoundError: No module named 'non_existent_module'"
"D:\MAGIC\outputs\logs\phase99_module_ZZ\99Z_import_error_test_READY.log","141","traceback","Traceback (most recent call last):"
"D:\MAGIC\outputs\logs\phase99_module_ZZ\99Z_import_error_test_READY.log","142","error","File ""D:\MAGIC\scripts\phase99\module_ZZ\99Z_import_error_test_READY.py"", line 1, in <module>"
"D:\MAGIC\outputs\logs\phase99_module_ZZ\99Z_import_error_test_READY.log","144","error","ModuleNotFoundError: No module named 'non_existent_module'"
"D:\MAGIC\outputs\logs\phase99_module_ZZ\99Z_unicode_error_test_READY.log","2","error","Running script: D:/MAGIC/scripts/phase99/module_ZZ/99Z_unicode_error_test_READY.py"
"D:\MAGIC\outputs\logs\phase99_module_ZZ\99Z_unicode_error_test_READY.log","7","traceback","Traceback (most recent call last):"
"D:\MAGIC\outputs\logs\phase99_module_ZZ\99Z_unicode_error_test_READY.log","8","error","File ""D:\MAGIC\scripts\phase99\module_ZZ\99Z_unicode_error_test_READY.py"", line 3, in <module>"
"D:\MAGIC\outputs\logs\phase99_module_ZZ\99Z_unicode_error_test_READY.log","11","error","UnicodeEncodeError: 'ascii' codec can't encode characters in position 12-14: ordinal not in range(128)"
"D:\MAGIC\outputs\logs\phase99_module_ZZ\99Z_unicode_error_test_READY.log","16","error","Running script: D:/MAGIC/scripts/phase99/module_ZZ/99Z_unicode_error_test_READY.py"
"D:\MAGIC\outputs\logs\phase99_module_ZZ\99Z_unicode_error_test_READY.log","21","traceback","Traceback (most recent call last):"
"D:\MAGIC\outputs\logs\phase99_module_ZZ\99Z_unicode_error_test_READY.log","22","error","File ""D:\MAGIC\scripts\phase99\module_ZZ\99Z_unicode_error_test_READY.py"", line 3, in <module>"
"D:\MAGIC\outputs\logs\phase99_module_ZZ\99Z_unicode_error_test_READY.log","25","error","UnicodeEncodeError: 'ascii' codec can't encode characters in position 12-14: ordinal not in range(128)"
"D:\MAGIC\outputs\logs\phase99_module_ZZ\99Z_unicode_error_test_READY.log","33","error","Running script: D:/MAGIC/scripts/phase99/module_ZZ/99Z_unicode_error_test_READY.py"
"D:\MAGIC\outputs\logs\phase99_module_ZZ\99Z_unicode_error_test_READY.log","38","traceback","Traceback (most recent call last):"
"D:\MAGIC\outputs\logs\phase99_module_ZZ\99Z_unicode_error_test_READY.log","39","error","File ""D:\MAGIC\scripts\phase99\module_ZZ\99Z_unicode_error_test_READY.py"", line 3, in <module>"
"D:\MAGIC\outputs\logs\phase99_module_ZZ\99Z_unicode_error_test_READY.log","42","error","UnicodeEncodeError: 'ascii' codec can't encode characters in position 12-14: ordinal not in range(128)"
"D:\MAGIC\outputs\logs\phase99_module_ZZ\99Z_unicode_error_test_READY.log","50","error","Running script: D:/MAGIC/scripts/phase99/module_ZZ/99Z_unicode_error_test_READY.py"
"D:\MAGIC\outputs\logs\phase99_module_ZZ\99Z_unicode_error_test_READY.log","55","traceback","Traceback (most recent call last):"
"D:\MAGIC\outputs\logs\phase99_module_ZZ\99Z_unicode_error_test_READY.log","56","error","File ""D:\MAGIC\scripts\phase99\module_ZZ\99Z_unicode_error_test_READY.py"", line 3, in <module>"
"D:\MAGIC\outputs\logs\phase99_module_ZZ\99Z_unicode_error_test_READY.log","59","error","UnicodeEncodeError: 'ascii' codec can't encode characters in position 12-14: ordinal not in range(128)"
"D:\MAGIC\outputs\logs\phase99_module_ZZ\99Z_unicode_error_test_READY.log","67","error","Running script: D:/MAGIC/scripts/phase99/module_ZZ/99Z_unicode_error_test_READY.py"
"D:\MAGIC\outputs\logs\phase99_module_ZZ\99Z_unicode_error_test_READY.log","72","traceback","Traceback (most recent call last):"
"D:\MAGIC\outputs\logs\phase99_module_ZZ\99Z_unicode_error_test_READY.log","73","error","File ""D:\MAGIC\scripts\phase99\module_ZZ\99Z_unicode_error_test_READY.py"", line 3, in <module>"
"D:\MAGIC\outputs\logs\phase99_module_ZZ\99Z_unicode_error_test_READY.log","76","error","UnicodeEncodeError: 'ascii' codec can't encode characters in position 12-14: ordinal not in range(128)"
"D:\MAGIC\outputs\logs\phase99_module_ZZ\99Z_unicode_error_test_READY.log","84","error","Running script: D:/MAGIC/scripts/phase99/module_ZZ/99Z_unicode_error_test_READY.py"
"D:\MAGIC\outputs\logs\phase99_module_ZZ\99Z_unicode_error_test_READY.log","89","traceback","Traceback (most recent call last):"
"D:\MAGIC\outputs\logs\phase99_module_ZZ\99Z_unicode_error_test_READY.log","90","error","File ""D:\MAGIC\scripts\phase99\module_ZZ\99Z_unicode_error_test_READY.py"", line 3, in <module>"
"D:\MAGIC\outputs\logs\phase99_module_ZZ\99Z_unicode_error_test_READY.log","93","error","UnicodeEncodeError: 'ascii' codec can't encode characters in position 12-14: ordinal not in range(128)"
"D:\MAGIC\outputs\logs\phase99_module_ZZ\99Z_unicode_error_test_READY.log","101","error","Running script: D:/MAGIC/scripts/phase99/module_ZZ/99Z_unicode_error_test_READY.py"
"D:\MAGIC\outputs\logs\phase99_module_ZZ\99Z_unicode_error_test_READY.log","106","traceback","Traceback (most recent call last):"
"D:\MAGIC\outputs\logs\phase99_module_ZZ\99Z_unicode_error_test_READY.log","107","error","File ""D:\MAGIC\scripts\phase99\module_ZZ\99Z_unicode_error_test_READY.py"", line 3, in <module>"
"D:\MAGIC\outputs\logs\phase99_module_ZZ\99Z_unicode_error_test_READY.log","110","error","UnicodeEncodeError: 'ascii' codec can't encode characters in position 12-14: ordinal not in range(128)"
"D:\MAGIC\outputs\logs\phase99_module_ZZ\99Z_unicode_error_test_READY.log","122","traceback","Traceback (most recent call last):"
"D:\MAGIC\outputs\logs\phase99_module_ZZ\99Z_unicode_error_test_READY.log","123","error","File ""D:\MAGIC\scripts\phase99\module_ZZ\99Z_unicode_error_test_READY.py"", line 3, in <module>"
"D:\MAGIC\outputs\logs\phase99_module_ZZ\99Z_unicode_error_test_READY.log","126","error","UnicodeEncodeError: 'ascii' codec can't encode characters in position 12-14: ordinal not in range(128)"
"D:\MAGIC\outputs\logs\phase99_module_ZZ\99Z_unicode_error_test_READY.log","136","traceback","Traceback (most recent call last):"
"D:\MAGIC\outputs\logs\phase99_module_ZZ\99Z_unicode_error_test_READY.log","137","error","File ""D:\MAGIC\scripts\phase99\module_ZZ\99Z_unicode_error_test_READY.py"", line 3, in <module>"
"D:\MAGIC\outputs\logs\phase99_module_ZZ\99Z_unicode_error_test_READY.log","140","error","UnicodeEncodeError: 'ascii' codec can't encode characters in position 12-14: ordinal not in range(128)"
"D:\MAGIC\outputs\logs\phase99_module_ZZ\99Z_unicode_error_test_READY.log","150","traceback","Traceback (most recent call last):"
"D:\MAGIC\outputs\logs\phase99_module_ZZ\99Z_unicode_error_test_READY.log","151","error","File ""D:\MAGIC\scripts\phase99\module_ZZ\99Z_unicode_error_test_READY.py"", line 3, in <module>"
"D:\MAGIC\outputs\logs\phase99_module_ZZ\99Z_unicode_error_test_READY.log","154","error","UnicodeEncodeError: 'ascii' codec can't encode characters in position 12-14: ordinal not in range(128)"
"D:\MAGIC\outputs\logs\phaseMAGIC\module_scripts\99Z_file_not_found_test_READY.py_2025-08-04_17-47-36.log","3","traceback","Traceback (most recent call last):"
"D:\MAGIC\outputs\logs\phaseMAGIC\module_scripts\99Z_file_not_found_test_READY.py_2025-08-04_17-47-36.log","7","error","FileNotFoundError: [Errno 2] No such file or directory: 'non_existent_input.txt'"
"D:\MAGIC\outputs\logs\phaseMAGIC\module_scripts\99Z_import_error_test_READY.py_2025-08-04_17-47-36.log","3","traceback","Traceback (most recent call last):"
"D:\MAGIC\outputs\logs\phaseMAGIC\module_scripts\99Z_import_error_test_READY.py_2025-08-04_17-47-36.log","4","error","File ""D:\MAGIC\scripts\phase99\module_ZZ\99Z_import_error_test_READY.py"", line 1, in <module>"
"D:\MAGIC\outputs\logs\phaseMAGIC\module_scripts\99Z_import_error_test_READY.py_2025-08-04_17-47-36.log","6","error","ModuleNotFoundError: No module named 'non_existent_module'"
"D:\MAGIC\outputs\logs\phaseMAGIC\module_scripts\99Z_import_error_test_READY.py_2025-08-04_17-47-36.log","9","traceback","Traceback (most recent call last):"
"D:\MAGIC\outputs\logs\phaseMAGIC\module_scripts\99Z_import_error_test_READY.py_2025-08-04_17-47-36.log","10","error","File ""D:\MAGIC\scripts\phase99\module_ZZ\99Z_import_error_test_READY.py"", line 1, in <module>"
"D:\MAGIC\outputs\logs\phaseMAGIC\module_scripts\99Z_import_error_test_READY.py_2025-08-04_17-47-36.log","12","error","ModuleNotFoundError: No module named 'non_existent_module'"
"D:\MAGIC\outputs\logs\phaseMAGIC\module_scripts\99Z_import_error_test_READY.py_2025-08-04_17-47-36.log","15","traceback","Traceback (most recent call last):"
"D:\MAGIC\outputs\logs\phaseMAGIC\module_scripts\99Z_import_error_test_READY.py_2025-08-04_17-47-36.log","16","error","File ""D:\MAGIC\scripts\phase99\module_ZZ\99Z_import_error_test_READY.py"", line 1, in <module>"
"D:\MAGIC\outputs\logs\phaseMAGIC\module_scripts\99Z_import_error_test_READY.py_2025-08-04_17-47-36.log","18","error","ModuleNotFoundError: No module named 'non_existent_module'"
"D:\MAGIC\outputs\logs\phaseMAGIC\module_scripts\99Z_unicode_error_test_READY.py_2025-08-04_17-47-36.log","3","traceback","Traceback (most recent call last):"
"D:\MAGIC\outputs\logs\phaseMAGIC\module_scripts\99Z_unicode_error_test_READY.py_2025-08-04_17-47-36.log","4","error","File ""D:\MAGIC\scripts\phase99\module_ZZ\99Z_unicode_error_test_READY.py"", line 3, in <module>"
"D:\MAGIC\outputs\logs\phaseMAGIC\module_scripts\99Z_unicode_error_test_READY.py_2025-08-04_17-47-36.log","7","error","UnicodeEncodeError: 'ascii' codec can't encode characters in position 12-14: ordinal not in range(128)"
"D:\MAGIC\outputs\logs\phaseMAGIC\module_scripts\99Z_unicode_error_test_READY.py_2025-08-04_17-47-36.log","10","traceback","Traceback (most recent call last):"
"D:\MAGIC\outputs\logs\phaseMAGIC\module_scripts\99Z_unicode_error_test_READY.py_2025-08-04_17-47-36.log","11","error","File ""D:\MAGIC\scripts\phase99\module_ZZ\99Z_unicode_error_test_READY.py"", line 3, in <module>"
"D:\MAGIC\outputs\logs\phaseMAGIC\module_scripts\99Z_unicode_error_test_READY.py_2025-08-04_17-47-36.log","14","error","UnicodeEncodeError: 'ascii' codec can't encode characters in position 12-14: ordinal not in range(128)"
"D:\MAGIC\outputs\logs\phaseMAGIC\module_scripts\99Z_unicode_error_test_READY.py_2025-08-04_17-47-36.log","17","traceback","Traceback (most recent call last):"
"D:\MAGIC\outputs\logs\phaseMAGIC\module_scripts\99Z_unicode_error_test_READY.py_2025-08-04_17-47-36.log","18","error","File ""D:\MAGIC\scripts\phase99\module_ZZ\99Z_unicode_error_test_READY.py"", line 3, in <module>"
"D:\MAGIC\outputs\logs\phaseMAGIC\module_scripts\99Z_unicode_error_test_READY.py_2025-08-04_17-47-36.log","21","error","UnicodeEncodeError: 'ascii' codec can't encode characters in position 12-14: ordinal not in range(128)"
"D:\MAGIC\outputs\logs\unknown\unknown\11A_error_log_monitor_READY.py_2025-08-04_19-33-40.log","3","error","Running 11A_error_log_monitor_READY.py placeholder."
"D:\MAGIC\outputs\logs\unknown\unknown\11A_error_log_monitor_READY.py_2025-08-04_19-37-36.log","3","error","Running 11A_error_log_monitor_READY.py placeholder."
"D:\MAGIC\outputs\logs\unknown\unknown\11A_error_log_monitor_READY.py_2025-08-04_19-38-54.log","3","error","Running 11A_error_log_monitor_READY.py placeholder."
"D:\MAGIC\outputs\logs\unknown\unknown\11A_error_log_monitor_READY.py_2025-08-05_11-53-29.log","3","error","Running 11A_error_log_monitor_READY.py placeholder."
"D:\MAGIC\outputs\logs\unknown\unknown\11F_error_pattern_analyzer_READY.py_2025-08-04_19-33-40.log","3","error","âœ… [11F_error_pattern_analyzer_READY.py] executed successfully (stub mode)."
"D:\MAGIC\outputs\logs\unknown\unknown\11F_error_pattern_analyzer_READY.py_2025-08-04_19-37-36.log","3","error","âœ… [11F_error_pattern_analyzer_READY.py] executed successfully (stub mode)."
"D:\MAGIC\outputs\logs\unknown\unknown\11F_error_pattern_analyzer_READY.py_2025-08-04_19-38-54.log","3","error","âœ… [11F_error_pattern_analyzer_READY.py] executed successfully (stub mode)."
"D:\MAGIC\outputs\logs\unknown\unknown\11F_error_pattern_analyzer_READY.py_2025-08-05_11-53-29.log","3","error","âœ… [11F_error_pattern_analyzer_READY.py] executed successfully (stub mode)."
"D:\MAGIC\outputs\logs\unknown\unknown\11R_silent_error_logger_READY.py_2025-08-04_19-33-40.log","3","error","âœ… [11R_silent_error_logger_READY.py] executed successfully (stub mode)."
"D:\MAGIC\outputs\logs\unknown\unknown\11R_silent_error_logger_READY.py_2025-08-04_19-37-36.log","3","error","âœ… [11R_silent_error_logger_READY.py] executed successfully (stub mode)."
"D:\MAGIC\outputs\logs\unknown\unknown\11R_silent_error_logger_READY.py_2025-08-04_19-38-54.log","3","error","âœ… [11R_silent_error_logger_READY.py] executed successfully (stub mode)."
"D:\MAGIC\outputs\logs\unknown\unknown\11R_silent_error_logger_READY.py_2025-08-05_11-53-29.log","3","error","âœ… [11R_silent_error_logger_READY.py] executed successfully (stub mode)."
"D:\MAGIC\outputs\logs\unknown\unknown\99Z_import_error_test_READY.py_2025-08-04_17-49-08.log","5","traceback","Traceback (most recent call last):"
"D:\MAGIC\outputs\logs\unknown\unknown\99Z_import_error_test_READY.py_2025-08-04_17-49-08.log","6","error","File ""D:\MAGIC\scripts\phase99\module_ZZ\99Z_import_error_test_READY.py"", line 1, in <module>"
"D:\MAGIC\outputs\logs\unknown\unknown\99Z_import_error_test_READY.py_2025-08-04_17-49-08.log","8","error","ModuleNotFoundError: No module named 'non_existent_module'"
"D:\MAGIC\outputs\logs\unknown\unknown\99Z_import_error_test_READY.py_2025-08-04_17-49-08.log","16","traceback","Traceback (most recent call last):"
"D:\MAGIC\outputs\logs\unknown\unknown\99Z_import_error_test_READY.py_2025-08-04_17-49-08.log","17","error","File ""D:\MAGIC\scripts\phase99\module_ZZ\99Z_import_error_test_READY.py"", line 1, in <module>"
"D:\MAGIC\outputs\logs\unknown\unknown\99Z_import_error_test_READY.py_2025-08-04_17-49-08.log","19","error","ModuleNotFoundError: No module named 'non_existent_module'"
"D:\MAGIC\outputs\logs\unknown\unknown\99Z_import_error_test_READY.py_2025-08-04_17-49-08.log","27","traceback","Traceback (most recent call last):"
"D:\MAGIC\outputs\logs\unknown\unknown\99Z_import_error_test_READY.py_2025-08-04_17-49-08.log","28","error","File ""D:\MAGIC\scripts\phase99\module_ZZ\99Z_import_error_test_READY.py"", line 1, in <module>"
"D:\MAGIC\outputs\logs\unknown\unknown\99Z_import_error_test_READY.py_2025-08-04_17-49-08.log","30","error","ModuleNotFoundError: No module named 'non_existent_module'"
"D:\MAGIC\outputs\logs\unknown\unknown\99Z_import_error_test_READY.py_2025-08-04_19-33-40.log","5","traceback","Traceback (most recent call last):"
"D:\MAGIC\outputs\logs\unknown\unknown\99Z_import_error_test_READY.py_2025-08-04_19-33-40.log","6","error","File ""D:\MAGIC\scripts\phase99\module_ZZ\99Z_import_error_test_READY.py"", line 1, in <module>"
"D:\MAGIC\outputs\logs\unknown\unknown\99Z_import_error_test_READY.py_2025-08-04_19-33-40.log","8","error","ModuleNotFoundError: No module named 'non_existent_module'"
"D:\MAGIC\outputs\logs\unknown\unknown\99Z_import_error_test_READY.py_2025-08-04_19-33-40.log","16","traceback","Traceback (most recent call last):"
"D:\MAGIC\outputs\logs\unknown\unknown\99Z_import_error_test_READY.py_2025-08-04_19-33-40.log","17","error","File ""D:\MAGIC\scripts\phase99\module_ZZ\99Z_import_error_test_READY.py"", line 1, in <module>"
"D:\MAGIC\outputs\logs\unknown\unknown\99Z_import_error_test_READY.py_2025-08-04_19-33-40.log","19","error","ModuleNotFoundError: No module named 'non_existent_module'"
"D:\MAGIC\outputs\logs\unknown\unknown\99Z_import_error_test_READY.py_2025-08-04_19-33-40.log","27","traceback","Traceback (most recent call last):"
"D:\MAGIC\outputs\logs\unknown\unknown\99Z_import_error_test_READY.py_2025-08-04_19-33-40.log","28","error","File ""D:\MAGIC\scripts\phase99\module_ZZ\99Z_import_error_test_READY.py"", line 1, in <module>"
"D:\MAGIC\outputs\logs\unknown\unknown\99Z_import_error_test_READY.py_2025-08-04_19-33-40.log","30","error","ModuleNotFoundError: No module named 'non_existent_module'"
"D:\MAGIC\outputs\logs\unknown\unknown\99Z_import_error_test_READY.py_2025-08-04_19-37-36.log","5","traceback","Traceback (most recent call last):"
"D:\MAGIC\outputs\logs\unknown\unknown\99Z_import_error_test_READY.py_2025-08-04_19-37-36.log","6","error","File ""D:\MAGIC\scripts\phase99\module_ZZ\99Z_import_error_test_READY.py"", line 1, in <module>"
"D:\MAGIC\outputs\logs\unknown\unknown\99Z_import_error_test_READY.py_2025-08-04_19-37-36.log","8","error","ModuleNotFoundError: No module named 'non_existent_module'"
"D:\MAGIC\outputs\logs\unknown\unknown\99Z_import_error_test_READY.py_2025-08-04_19-37-36.log","16","traceback","Traceback (most recent call last):"
"D:\MAGIC\outputs\logs\unknown\unknown\99Z_import_error_test_READY.py_2025-08-04_19-37-36.log","17","error","File ""D:\MAGIC\scripts\phase99\module_ZZ\99Z_import_error_test_READY.py"", line 1, in <module>"
"D:\MAGIC\outputs\logs\unknown\unknown\99Z_import_error_test_READY.py_2025-08-04_19-37-36.log","19","error","ModuleNotFoundError: No module named 'non_existent_module'"
"D:\MAGIC\outputs\logs\unknown\unknown\99Z_import_error_test_READY.py_2025-08-04_19-37-36.log","27","traceback","Traceback (most recent call last):"
"D:\MAGIC\outputs\logs\unknown\unknown\99Z_import_error_test_READY.py_2025-08-04_19-37-36.log","28","error","File ""D:\MAGIC\scripts\phase99\module_ZZ\99Z_import_error_test_READY.py"", line 1, in <module>"
"D:\MAGIC\outputs\logs\unknown\unknown\99Z_import_error_test_READY.py_2025-08-04_19-37-36.log","30","error","ModuleNotFoundError: No module named 'non_existent_module'"
"D:\MAGIC\outputs\logs\unknown\unknown\99Z_import_error_test_READY.py_2025-08-04_19-38-54.log","5","traceback","Traceback (most recent call last):"
"D:\MAGIC\outputs\logs\unknown\unknown\99Z_import_error_test_READY.py_2025-08-04_19-38-54.log","6","error","File ""D:\MAGIC\scripts\phase99\module_ZZ\99Z_import_error_test_READY.py"", line 1, in <module>"
"D:\MAGIC\outputs\logs\unknown\unknown\99Z_import_error_test_READY.py_2025-08-04_19-38-54.log","8","error","ModuleNotFoundError: No module named 'non_existent_module'"
"D:\MAGIC\outputs\logs\unknown\unknown\99Z_import_error_test_READY.py_2025-08-04_19-38-54.log","16","traceback","Traceback (most recent call last):"
"D:\MAGIC\outputs\logs\unknown\unknown\99Z_import_error_test_READY.py_2025-08-04_19-38-54.log","17","error","File ""D:\MAGIC\scripts\phase99\module_ZZ\99Z_import_error_test_READY.py"", line 1, in <module>"
"D:\MAGIC\outputs\logs\unknown\unknown\99Z_import_error_test_READY.py_2025-08-04_19-38-54.log","19","error","ModuleNotFoundError: No module named 'non_existent_module'"
"D:\MAGIC\outputs\logs\unknown\unknown\99Z_import_error_test_READY.py_2025-08-04_19-38-54.log","27","traceback","Traceback (most recent call last):"
"D:\MAGIC\outputs\logs\unknown\unknown\99Z_import_error_test_READY.py_2025-08-04_19-38-54.log","28","error","File ""D:\MAGIC\scripts\phase99\module_ZZ\99Z_import_error_test_READY.py"", line 1, in <module>"
"D:\MAGIC\outputs\logs\unknown\unknown\99Z_import_error_test_READY.py_2025-08-04_19-38-54.log","30","error","ModuleNotFoundError: No module named 'non_existent_module'"
"D:\MAGIC\outputs\logs\unknown\unknown\99Z_import_error_test_READY.py_2025-08-05_11-53-29.log","5","traceback","Traceback (most recent call last):"
"D:\MAGIC\outputs\logs\unknown\unknown\99Z_import_error_test_READY.py_2025-08-05_11-53-29.log","6","error","File ""D:\MAGIC\scripts\phase99\module_ZZ\99Z_import_error_test_READY.py"", line 1, in <module>"
"D:\MAGIC\outputs\logs\unknown\unknown\99Z_import_error_test_READY.py_2025-08-05_11-53-29.log","8","error","ModuleNotFoundError: No module named 'non_existent_module'"
"D:\MAGIC\outputs\logs\unknown\unknown\99Z_import_error_test_READY.py_2025-08-05_11-53-29.log","16","traceback","Traceback (most recent call last):"
"D:\MAGIC\outputs\logs\unknown\unknown\99Z_import_error_test_READY.py_2025-08-05_11-53-29.log","17","error","File ""D:\MAGIC\scripts\phase99\module_ZZ\99Z_import_error_test_READY.py"", line 1, in <module>"
"D:\MAGIC\outputs\logs\unknown\unknown\99Z_import_error_test_READY.py_2025-08-05_11-53-29.log","19","error","ModuleNotFoundError: No module named 'non_existent_module'"
"D:\MAGIC\outputs\logs\unknown\unknown\99Z_import_error_test_READY.py_2025-08-05_11-53-29.log","27","traceback","Traceback (most recent call last):"
"D:\MAGIC\outputs\logs\unknown\unknown\99Z_import_error_test_READY.py_2025-08-05_11-53-29.log","28","error","File ""D:\MAGIC\scripts\phase99\module_ZZ\99Z_import_error_test_READY.py"", line 1, in <module>"
"D:\MAGIC\outputs\logs\unknown\unknown\99Z_import_error_test_READY.py_2025-08-05_11-53-29.log","30","error","ModuleNotFoundError: No module named 'non_existent_module'"
"D:\MAGIC\outputs\logs\unknown\unknown\99Z_unicode_error_test_READY.py_2025-08-04_17-49-08.log","5","traceback","Traceback (most recent call last):"
"D:\MAGIC\outputs\logs\unknown\unknown\99Z_unicode_error_test_READY.py_2025-08-04_17-49-08.log","6","error","File ""D:\MAGIC\scripts\phase99\module_ZZ\99Z_unicode_error_test_READY.py"", line 3, in <module>"
"D:\MAGIC\outputs\logs\unknown\unknown\99Z_unicode_error_test_READY.py_2025-08-04_17-49-08.log","9","error","UnicodeEncodeError: 'ascii' codec can't encode characters in position 12-14: ordinal not in range(128)"
"D:\MAGIC\outputs\logs\unknown\unknown\99Z_unicode_error_test_READY.py_2025-08-04_17-49-08.log","12","error","AUTO-FIXED: Cleaned unicode errors from output."
"D:\MAGIC\outputs\logs\unknown\unknown\99Z_unicode_error_test_READY.py_2025-08-04_17-49-08.log","17","traceback","Traceback (most recent call last):"
"D:\MAGIC\outputs\logs\unknown\unknown\99Z_unicode_error_test_READY.py_2025-08-04_17-49-08.log","18","error","File ""D:\MAGIC\scripts\phase99\module_ZZ\99Z_unicode_error_test_READY.py"", line 3, in <module>"
"D:\MAGIC\outputs\logs\unknown\unknown\99Z_unicode_error_test_READY.py_2025-08-04_17-49-08.log","21","error","UnicodeEncodeError: 'ascii' codec can't encode characters in position 12-14: ordinal not in range(128)"
"D:\MAGIC\outputs\logs\unknown\unknown\99Z_unicode_error_test_READY.py_2025-08-04_17-49-08.log","24","error","AUTO-FIXED: Cleaned unicode errors from output."
"D:\MAGIC\outputs\logs\unknown\unknown\99Z_unicode_error_test_READY.py_2025-08-04_17-49-08.log","29","traceback","Traceback (most recent call last):"
"D:\MAGIC\outputs\logs\unknown\unknown\99Z_unicode_error_test_READY.py_2025-08-04_17-49-08.log","30","error","File ""D:\MAGIC\scripts\phase99\module_ZZ\99Z_unicode_error_test_READY.py"", line 3, in <module>"
"D:\MAGIC\outputs\logs\unknown\unknown\99Z_unicode_error_test_READY.py_2025-08-04_17-49-08.log","33","error","UnicodeEncodeError: 'ascii' codec can't encode characters in position 12-14: ordinal not in range(128)"
"D:\MAGIC\outputs\logs\unknown\unknown\99Z_unicode_error_test_READY.py_2025-08-04_17-49-08.log","36","error","AUTO-FIXED: Cleaned unicode errors from output."
"D:\MAGIC\outputs\logs\unknown\unknown\99Z_unicode_error_test_READY.py_2025-08-04_19-33-40.log","5","traceback","Traceback (most recent call last):"
"D:\MAGIC\outputs\logs\unknown\unknown\99Z_unicode_error_test_READY.py_2025-08-04_19-33-40.log","6","error","File ""D:\MAGIC\scripts\phase99\module_ZZ\99Z_unicode_error_test_READY.py"", line 3, in <module>"
"D:\MAGIC\outputs\logs\unknown\unknown\99Z_unicode_error_test_READY.py_2025-08-04_19-33-40.log","9","error","UnicodeEncodeError: 'ascii' codec can't encode characters in position 12-14: ordinal not in range(128)"
"D:\MAGIC\outputs\logs\unknown\unknown\99Z_unicode_error_test_READY.py_2025-08-04_19-33-40.log","12","error","AUTO-FIXED: Cleaned unicode errors from output."
"D:\MAGIC\outputs\logs\unknown\unknown\99Z_unicode_error_test_READY.py_2025-08-04_19-33-40.log","17","traceback","Traceback (most recent call last):"
"D:\MAGIC\outputs\logs\unknown\unknown\99Z_unicode_error_test_READY.py_2025-08-04_19-33-40.log","18","error","File ""D:\MAGIC\scripts\phase99\module_ZZ\99Z_unicode_error_test_READY.py"", line 3, in <module>"
"D:\MAGIC\outputs\logs\unknown\unknown\99Z_unicode_error_test_READY.py_2025-08-04_19-33-40.log","21","error","UnicodeEncodeError: 'ascii' codec can't encode characters in position 12-14: ordinal not in range(128)"
"D:\MAGIC\outputs\logs\unknown\unknown\99Z_unicode_error_test_READY.py_2025-08-04_19-33-40.log","24","error","AUTO-FIXED: Cleaned unicode errors from output."
"D:\MAGIC\outputs\logs\unknown\unknown\99Z_unicode_error_test_READY.py_2025-08-04_19-33-40.log","29","traceback","Traceback (most recent call last):"
"D:\MAGIC\outputs\logs\unknown\unknown\99Z_unicode_error_test_READY.py_2025-08-04_19-33-40.log","30","error","File ""D:\MAGIC\scripts\phase99\module_ZZ\99Z_unicode_error_test_READY.py"", line 3, in <module>"
"D:\MAGIC\outputs\logs\unknown\unknown\99Z_unicode_error_test_READY.py_2025-08-04_19-33-40.log","33","error","UnicodeEncodeError: 'ascii' codec can't encode characters in position 12-14: ordinal not in range(128)"
"D:\MAGIC\outputs\logs\unknown\unknown\99Z_unicode_error_test_READY.py_2025-08-04_19-33-40.log","36","error","AUTO-FIXED: Cleaned unicode errors from output."
"D:\MAGIC\outputs\logs\unknown\unknown\99Z_unicode_error_test_READY.py_2025-08-04_19-37-36.log","5","traceback","Traceback (most recent call last):"
"D:\MAGIC\outputs\logs\unknown\unknown\99Z_unicode_error_test_READY.py_2025-08-04_19-37-36.log","6","error","File ""D:\MAGIC\scripts\phase99\module_ZZ\99Z_unicode_error_test_READY.py"", line 3, in <module>"
"D:\MAGIC\outputs\logs\unknown\unknown\99Z_unicode_error_test_READY.py_2025-08-04_19-37-36.log","9","error","UnicodeEncodeError: 'ascii' codec can't encode characters in position 12-14: ordinal not in range(128)"
"D:\MAGIC\outputs\logs\unknown\unknown\99Z_unicode_error_test_READY.py_2025-08-04_19-37-36.log","12","error","AUTO-FIXED: Cleaned unicode errors from output."
"D:\MAGIC\outputs\logs\unknown\unknown\99Z_unicode_error_test_READY.py_2025-08-04_19-37-36.log","17","traceback","Traceback (most recent call last):"
"D:\MAGIC\outputs\logs\unknown\unknown\99Z_unicode_error_test_READY.py_2025-08-04_19-37-36.log","18","error","File ""D:\MAGIC\scripts\phase99\module_ZZ\99Z_unicode_error_test_READY.py"", line 3, in <module>"
"D:\MAGIC\outputs\logs\unknown\unknown\99Z_unicode_error_test_READY.py_2025-08-04_19-37-36.log","21","error","UnicodeEncodeError: 'ascii' codec can't encode characters in position 12-14: ordinal not in range(128)"
"D:\MAGIC\outputs\logs\unknown\unknown\99Z_unicode_error_test_READY.py_2025-08-04_19-37-36.log","24","error","AUTO-FIXED: Cleaned unicode errors from output."
"D:\MAGIC\outputs\logs\unknown\unknown\99Z_unicode_error_test_READY.py_2025-08-04_19-37-36.log","29","traceback","Traceback (most recent call last):"
"D:\MAGIC\outputs\logs\unknown\unknown\99Z_unicode_error_test_READY.py_2025-08-04_19-37-36.log","30","error","File ""D:\MAGIC\scripts\phase99\module_ZZ\99Z_unicode_error_test_READY.py"", line 3, in <module>"
"D:\MAGIC\outputs\logs\unknown\unknown\99Z_unicode_error_test_READY.py_2025-08-04_19-37-36.log","33","error","UnicodeEncodeError: 'ascii' codec can't encode characters in position 12-14: ordinal not in range(128)"
"D:\MAGIC\outputs\logs\unknown\unknown\99Z_unicode_error_test_READY.py_2025-08-04_19-37-36.log","36","error","AUTO-FIXED: Cleaned unicode errors from output."
"D:\MAGIC\outputs\logs\unknown\unknown\99Z_unicode_error_test_READY.py_2025-08-04_19-38-54.log","5","traceback","Traceback (most recent call last):"
"D:\MAGIC\outputs\logs\unknown\unknown\99Z_unicode_error_test_READY.py_2025-08-04_19-38-54.log","6","error","File ""D:\MAGIC\scripts\phase99\module_ZZ\99Z_unicode_error_test_READY.py"", line 3, in <module>"
"D:\MAGIC\outputs\logs\unknown\unknown\99Z_unicode_error_test_READY.py_2025-08-04_19-38-54.log","9","error","UnicodeEncodeError: 'ascii' codec can't encode characters in position 12-14: ordinal not in range(128)"
"D:\MAGIC\outputs\logs\unknown\unknown\99Z_unicode_error_test_READY.py_2025-08-04_19-38-54.log","12","error","AUTO-FIXED: Cleaned unicode errors from output."
"D:\MAGIC\outputs\logs\unknown\unknown\99Z_unicode_error_test_READY.py_2025-08-04_19-38-54.log","17","traceback","Traceback (most recent call last):"
"D:\MAGIC\outputs\logs\unknown\unknown\99Z_unicode_error_test_READY.py_2025-08-04_19-38-54.log","18","error","File ""D:\MAGIC\scripts\phase99\module_ZZ\99Z_unicode_error_test_READY.py"", line 3, in <module>"
"D:\MAGIC\outputs\logs\unknown\unknown\99Z_unicode_error_test_READY.py_2025-08-04_19-38-54.log","21","error","UnicodeEncodeError: 'ascii' codec can't encode characters in position 12-14: ordinal not in range(128)"
"D:\MAGIC\outputs\logs\unknown\unknown\99Z_unicode_error_test_READY.py_2025-08-04_19-38-54.log","24","error","AUTO-FIXED: Cleaned unicode errors from output."
"D:\MAGIC\outputs\logs\unknown\unknown\99Z_unicode_error_test_READY.py_2025-08-04_19-38-54.log","29","traceback","Traceback (most recent call last):"
"D:\MAGIC\outputs\logs\unknown\unknown\99Z_unicode_error_test_READY.py_2025-08-04_19-38-54.log","30","error","File ""D:\MAGIC\scripts\phase99\module_ZZ\99Z_unicode_error_test_READY.py"", line 3, in <module>"
"D:\MAGIC\outputs\logs\unknown\unknown\99Z_unicode_error_test_READY.py_2025-08-04_19-38-54.log","33","error","UnicodeEncodeError: 'ascii' codec can't encode characters in position 12-14: ordinal not in range(128)"
"D:\MAGIC\outputs\logs\unknown\unknown\99Z_unicode_error_test_READY.py_2025-08-04_19-38-54.log","36","error","AUTO-FIXED: Cleaned unicode errors from output."
"D:\MAGIC\outputs\logs\unknown\unknown\99Z_unicode_error_test_READY.py_2025-08-05_11-53-29.log","5","traceback","Traceback (most recent call last):"
"D:\MAGIC\outputs\logs\unknown\unknown\99Z_unicode_error_test_READY.py_2025-08-05_11-53-29.log","6","error","File ""D:\MAGIC\scripts\phase99\module_ZZ\99Z_unicode_error_test_READY.py"", line 3, in <module>"
"D:\MAGIC\outputs\logs\unknown\unknown\99Z_unicode_error_test_READY.py_2025-08-05_11-53-29.log","9","error","UnicodeEncodeError: 'ascii' codec can't encode characters in position 12-14: ordinal not in range(128)"
"D:\MAGIC\outputs\logs\unknown\unknown\99Z_unicode_error_test_READY.py_2025-08-05_11-53-29.log","12","error","AUTO-FIXED: Cleaned unicode errors from output."
"D:\MAGIC\outputs\logs\unknown\unknown\99Z_unicode_error_test_READY.py_2025-08-05_11-53-29.log","17","traceback","Traceback (most recent call last):"
"D:\MAGIC\outputs\logs\unknown\unknown\99Z_unicode_error_test_READY.py_2025-08-05_11-53-29.log","18","error","File ""D:\MAGIC\scripts\phase99\module_ZZ\99Z_unicode_error_test_READY.py"", line 3, in <module>"
"D:\MAGIC\outputs\logs\unknown\unknown\99Z_unicode_error_test_READY.py_2025-08-05_11-53-29.log","21","error","UnicodeEncodeError: 'ascii' codec can't encode characters in position 12-14: ordinal not in range(128)"
"D:\MAGIC\outputs\logs\unknown\unknown\99Z_unicode_error_test_READY.py_2025-08-05_11-53-29.log","24","error","AUTO-FIXED: Cleaned unicode errors from output."
"D:\MAGIC\outputs\logs\unknown\unknown\99Z_unicode_error_test_READY.py_2025-08-05_11-53-29.log","29","traceback","Traceback (most recent call last):"
"D:\MAGIC\outputs\logs\unknown\unknown\99Z_unicode_error_test_READY.py_2025-08-05_11-53-29.log","30","error","File ""D:\MAGIC\scripts\phase99\module_ZZ\99Z_unicode_error_test_READY.py"", line 3, in <module>"
"D:\MAGIC\outputs\logs\unknown\unknown\99Z_unicode_error_test_READY.py_2025-08-05_11-53-29.log","33","error","UnicodeEncodeError: 'ascii' codec can't encode characters in position 12-14: ordinal not in range(128)"
"D:\MAGIC\outputs\logs\unknown\unknown\99Z_unicode_error_test_READY.py_2025-08-05_11-53-29.log","36","error","AUTO-FIXED: Cleaned unicode errors from output."
